Workbook

Sheet Datos
A1: PLANILLA SEGUIMIENTO — FNTC-161-2026 | Feb–Dic 2026 | Ingresar valores REALES en columna I (IGs) y columna H (IRs) — celdas azules
A3: SECCIÓN A — INDICADORES DE GESTIÓN POR ACTIVIDAD | Ingresar valor acumulado real en col I por cada período
A4: Cód. | B4: Indicador / Actividad | C4: Aspecto a Desarrollar | D4: Unidad | E4: Meta Total | F4: Meta Acum. Mes | G4: Período | H4: Mes # | I4: Valor Real | J4: Último Acum. | K4: % Desempeño | L4: Semáforo
A5: IG-01 | B5: Diseño Material Gráfico | C5: 1.1 — Diseño y desarrollo de piezas para campaña Colombia El País De La Belleza | D5: % Presup. Ejecutado | E5: 1 | F5: 0.090909091 | G5: Feb-26 | H5: 1 | I5: 0.45 | J5: =IFERROR(LOOKUP(2,1/(I5:I5<>""),I5:I5),"—") -> 0.45 | K5: =IFERROR(IF(OR(J5="—",F5=0),"",J5/F5*100),"—") -> 495 | L5: =IFERROR(IF(K5="","",IF(K5>=95,3,IF(K5>=80,2,1))),"—") -> 3
A6: IG-01 | B6: Diseño Material Gráfico | C6: 1.1 — Diseño y desarrollo de piezas para campaña Colombia El País De La Belleza | D6: % Presup. Ejecutado | E6: 1 | F6: 0.18181818 | G6: Mar-26 | H6: 2 | J6: =IFERROR(LOOKUP(2,1/(I5:I6<>""),I5:I6),"—") -> 0.45 | K6: =IFERROR(IF(OR(J6="—",F6=0),"",J6/F6*100),"—") -> 247.5 | L6: =IFERROR(IF(K6="","",IF(K6>=95,3,IF(K6>=80,2,1))),"—") -> 3
A7: IG-01 | B7: Diseño Material Gráfico | C7: 1.1 — Diseño y desarrollo de piezas para campaña Colombia El País De La Belleza | D7: % Presup. Ejecutado | E7: 1 | F7: 0.27272727 | G7: Abr-26 | H7: 3 | J7: =IFERROR(LOOKUP(2,1/(I5:I7<>""),I5:I7),"—") -> 0.45 | K7: =IFERROR(IF(OR(J7="—",F7=0),"",J7/F7*100),"—") -> 165 | L7: =IFERROR(IF(K7="","",IF(K7>=95,3,IF(K7>=80,2,1))),"—") -> 3
A8: IG-01 | B8: Diseño Material Gráfico | C8: 1.1 — Diseño y desarrollo de piezas para campaña Colombia El País De La Belleza | D8: % Presup. Ejecutado | E8: 1 | F8: 0.36363636 | G8: May-26 | H8: 4 | J8: =IFERROR(LOOKUP(2,1/(I5:I8<>""),I5:I8),"—") -> 0.45 | K8: =IFERROR(IF(OR(J8="—",F8=0),"",J8/F8*100),"—") -> 123.75 | L8: =IFERROR(IF(K8="","",IF(K8>=95,3,IF(K8>=80,2,1))),"—") -> 3
A9: IG-01 | B9: Diseño Material Gráfico | C9: 1.1 — Diseño y desarrollo de piezas para campaña Colombia El País De La Belleza | D9: % Presup. Ejecutado | E9: 1 | F9: 0.45454545 | G9: Jun-26 | H9: 5 | J9: =IFERROR(LOOKUP(2,1/(I5:I9<>""),I5:I9),"—") -> 0.45 | K9: =IFERROR(IF(OR(J9="—",F9=0),"",J9/F9*100),"—") -> 99 | L9: =IFERROR(IF(K9="","",IF(K9>=95,3,IF(K9>=80,2,1))),"—") -> 3
A10: IG-01 | B10: Diseño Material Gráfico | C10: 1.1 — Diseño y desarrollo de piezas para campaña Colombia El País De La Belleza | D10: % Presup. Ejecutado | E10: 1 | F10: 0.54545455 | G10: Jul-26 | H10: 6 | J10: =IFERROR(LOOKUP(2,1/(I5:I10<>""),I5:I10),"—") -> 0.45 | K10: =IFERROR(IF(OR(J10="—",F10=0),"",J10/F10*100),"—") -> 82.5 | L10: =IFERROR(IF(K10="","",IF(K10>=95,3,IF(K10>=80,2,1))),"—") -> 2
A11: IG-01 | B11: Diseño Material Gráfico | C11: 1.1 — Diseño y desarrollo de piezas para campaña Colombia El País De La Belleza | D11: % Presup. Ejecutado | E11: 1 | F11: 0.63636364 | G11: Ago-26 | H11: 7 | J11: =IFERROR(LOOKUP(2,1/(I5:I11<>""),I5:I11),"—") -> 0.45 | K11: =IFERROR(IF(OR(J11="—",F11=0),"",J11/F11*100),"—") -> 70.714286 | L11: =IFERROR(IF(K11="","",IF(K11>=95,3,IF(K11>=80,2,1))),"—") -> 1
A12: IG-01 | B12: Diseño Material Gráfico | C12: 1.1 — Diseño y desarrollo de piezas para campaña Colombia El País De La Belleza | D12: % Presup. Ejecutado | E12: 1 | F12: 0.72727273 | G12: Sep-26 | H12: 8 | J12: =IFERROR(LOOKUP(2,1/(I5:I12<>""),I5:I12),"—") -> 0.45 | K12: =IFERROR(IF(OR(J12="—",F12=0),"",J12/F12*100),"—") -> 61.875 | L12: =IFERROR(IF(K12="","",IF(K12>=95,3,IF(K12>=80,2,1))),"—") -> 1
A13: IG-01 | B13: Diseño Material Gráfico | C13: 1.1 — Diseño y desarrollo de piezas para campaña Colombia El País De La Belleza | D13: % Presup. Ejecutado | E13: 1 | F13: 0.81818182 | G13: Oct-26 | H13: 9 | J13: =IFERROR(LOOKUP(2,1/(I5:I13<>""),I5:I13),"—") -> 0.45 | K13: =IFERROR(IF(OR(J13="—",F13=0),"",J13/F13*100),"—") -> 55 | L13: =IFERROR(IF(K13="","",IF(K13>=95,3,IF(K13>=80,2,1))),"—") -> 1
A14: IG-01 | B14: Diseño Material Gráfico | C14: 1.1 — Diseño y desarrollo de piezas para campaña Colombia El País De La Belleza | D14: % Presup. Ejecutado | E14: 1 | F14: 0.90909091 | G14: Nov-26 | H14: 10 | J14: =IFERROR(LOOKUP(2,1/(I5:I14<>""),I5:I14),"—") -> 0.45 | K14: =IFERROR(IF(OR(J14="—",F14=0),"",J14/F14*100),"—") -> 49.5 | L14: =IFERROR(IF(K14="","",IF(K14>=95,3,IF(K14>=80,2,1))),"—") -> 1
A15: IG-01 | B15: Diseño Material Gráfico | C15: 1.1 — Diseño y desarrollo de piezas para campaña Colombia El País De La Belleza | D15: % Presup. Ejecutado | E15: 1 | F15: 1 | G15: Dic-26 | H15: 11 | J15: =IFERROR(LOOKUP(2,1/(I5:I15<>""),I5:I15),"—") -> 0.45 | K15: =IFERROR(IF(OR(J15="—",F15=0),"",J15/F15*100),"—") -> 45 | L15: =IFERROR(IF(K15="","",IF(K15>=95,3,IF(K15>=80,2,1))),"—") -> 1
A16: IG-02 | B16: Ejecución Pauta | C16: 1.2 — Estrategias en canales digitales, medios tradicionales y alternativos | D16: % Presup. Ejecutado | E16: 1 | F16: 0.090909091 | G16: Feb-26 | H16: 1 | I16: 0.58 | J16: =IFERROR(LOOKUP(2,1/(I16:I16<>""),I16:I16),"—") -> 0.58 | K16: =IFERROR(IF(OR(J16="—",F16=0),"",J16/F16*100),"—") -> 638 | L16: =IFERROR(IF(K16="","",IF(K16>=95,3,IF(K16>=80,2,1))),"—") -> 3
A17: IG-02 | B17: Ejecución Pauta | C17: 1.2 — Estrategias en canales digitales, medios tradicionales y alternativos | D17: % Presup. Ejecutado | E17: 1 | F17: 0.18181818 | G17: Mar-26 | H17: 2 | J17: =IFERROR(LOOKUP(2,1/(I16:I17<>""),I16:I17),"—") -> 0.58 | K17: =IFERROR(IF(OR(J17="—",F17=0),"",J17/F17*100),"—") -> 319 | L17: =IFERROR(IF(K17="","",IF(K17>=95,3,IF(K17>=80,2,1))),"—") -> 3
A18: IG-02 | B18: Ejecución Pauta | C18: 1.2 — Estrategias en canales digitales, medios tradicionales y alternativos | D18: % Presup. Ejecutado | E18: 1 | F18: 0.27272727 | G18: Abr-26 | H18: 3 | J18: =IFERROR(LOOKUP(2,1/(I16:I18<>""),I16:I18),"—") -> 0.58 | K18: =IFERROR(IF(OR(J18="—",F18=0),"",J18/F18*100),"—") -> 212.66667 | L18: =IFERROR(IF(K18="","",IF(K18>=95,3,IF(K18>=80,2,1))),"—") -> 3
A19: IG-02 | B19: Ejecución Pauta | C19: 1.2 — Estrategias en canales digitales, medios tradicionales y alternativos | D19: % Presup. Ejecutado | E19: 1 | F19: 0.36363636 | G19: May-26 | H19: 4 | J19: =IFERROR(LOOKUP(2,1/(I16:I19<>""),I16:I19),"—") -> 0.58 | K19: =IFERROR(IF(OR(J19="—",F19=0),"",J19/F19*100),"—") -> 159.5 | L19: =IFERROR(IF(K19="","",IF(K19>=95,3,IF(K19>=80,2,1))),"—") -> 3
A20: IG-02 | B20: Ejecución Pauta | C20: 1.2 — Estrategias en canales digitales, medios tradicionales y alternativos | D20: % Presup. Ejecutado | E20: 1 | F20: 0.45454545 | G20: Jun-26 | H20: 5 | J20: =IFERROR(LOOKUP(2,1/(I16:I20<>""),I16:I20),"—") -> 0.58 | K20: =IFERROR(IF(OR(J20="—",F20=0),"",J20/F20*100),"—") -> 127.6 | L20: =IFERROR(IF(K20="","",IF(K20>=95,3,IF(K20>=80,2,1))),"—") -> 3
A21: IG-02 | B21: Ejecución Pauta | C21: 1.2 — Estrategias en canales digitales, medios tradicionales y alternativos | D21: % Presup. Ejecutado | E21: 1 | F21: 0.54545455 | G21: Jul-26 | H21: 6 | J21: =IFERROR(LOOKUP(2,1/(I16:I21<>""),I16:I21),"—") -> 0.58 | K21: =IFERROR(IF(OR(J21="—",F21=0),"",J21/F21*100),"—") -> 106.33333 | L21: =IFERROR(IF(K21="","",IF(K21>=95,3,IF(K21>=80,2,1))),"—") -> 3
A22: IG-02 | B22: Ejecución Pauta | C22: 1.2 — Estrategias en canales digitales, medios tradicionales y alternativos | D22: % Presup. Ejecutado | E22: 1 | F22: 0.63636364 | G22: Ago-26 | H22: 7 | J22: =IFERROR(LOOKUP(2,1/(I16:I22<>""),I16:I22),"—") -> 0.58 | K22: =IFERROR(IF(OR(J22="—",F22=0),"",J22/F22*100),"—") -> 91.142857 | L22: =IFERROR(IF(K22="","",IF(K22>=95,3,IF(K22>=80,2,1))),"—") -> 2
A23: IG-02 | B23: Ejecución Pauta | C23: 1.2 — Estrategias en canales digitales, medios tradicionales y alternativos | D23: % Presup. Ejecutado | E23: 1 | F23: 0.72727273 | G23: Sep-26 | H23: 8 | J23: =IFERROR(LOOKUP(2,1/(I16:I23<>""),I16:I23),"—") -> 0.58 | K23: =IFERROR(IF(OR(J23="—",F23=0),"",J23/F23*100),"—") -> 79.75 | L23: =IFERROR(IF(K23="","",IF(K23>=95,3,IF(K23>=80,2,1))),"—") -> 1
A24: IG-02 | B24: Ejecución Pauta | C24: 1.2 — Estrategias en canales digitales, medios tradicionales y alternativos | D24: % Presup. Ejecutado | E24: 1 | F24: 0.81818182 | G24: Oct-26 | H24: 9 | J24: =IFERROR(LOOKUP(2,1/(I16:I24<>""),I16:I24),"—") -> 0.58 | K24: =IFERROR(IF(OR(J24="—",F24=0),"",J24/F24*100),"—") -> 70.888889 | L24: =IFERROR(IF(K24="","",IF(K24>=95,3,IF(K24>=80,2,1))),"—") -> 1
A25: IG-02 | B25: Ejecución Pauta | C25: 1.2 — Estrategias en canales digitales, medios tradicionales y alternativos | D25: % Presup. Ejecutado | E25: 1 | F25: 0.90909091 | G25: Nov-26 | H25: 10 | J25: =IFERROR(LOOKUP(2,1/(I16:I25<>""),I16:I25),"—") -> 0.58 | K25: =IFERROR(IF(OR(J25="—",F25=0),"",J25/F25*100),"—") -> 63.8 | L25: =IFERROR(IF(K25="","",IF(K25>=95,3,IF(K25>=80,2,1))),"—") -> 1
A26: IG-02 | B26: Ejecución Pauta | C26: 1.2 — Estrategias en canales digitales, medios tradicionales y alternativos | D26: % Presup. Ejecutado | E26: 1 | F26: 1 | G26: Dic-26 | H26: 11 | J26: =IFERROR(LOOKUP(2,1/(I16:I26<>""),I16:I26),"—") -> 0.58 | K26: =IFERROR(IF(OR(J26="—",F26=0),"",J26/F26*100),"—") -> 58 | L26: =IFERROR(IF(K26="","",IF(K26>=95,3,IF(K26>=80,2,1))),"—") -> 1
A27: IG-03 | B27: Actividades BTL | C27: 1.3 — Promoción de destinos y productos según estrategia de marca (≥32 activaciones) | D27: % Presup. Ejecutado | E27: 1 | F27: 0.090909091 | G27: Feb-26 | H27: 1 | I27: 0.62 | J27: =IFERROR(LOOKUP(2,1/(I27:I27<>""),I27:I27),"—") -> 0.62 | K27: =IFERROR(IF(OR(J27="—",F27=0),"",J27/F27*100),"—") -> 682 | L27: =IFERROR(IF(K27="","",IF(K27>=95,3,IF(K27>=80,2,1))),"—") -> 3
A28: IG-03 | B28: Actividades BTL | C28: 1.3 — Promoción de destinos y productos según estrategia de marca (≥32 activaciones) | D28: % Presup. Ejecutado | E28: 1 | F28: 0.18181818 | G28: Mar-26 | H28: 2 | J28: =IFERROR(LOOKUP(2,1/(I27:I28<>""),I27:I28),"—") -> 0.62 | K28: =IFERROR(IF(OR(J28="—",F28=0),"",J28/F28*100),"—") -> 341 | L28: =IFERROR(IF(K28="","",IF(K28>=95,3,IF(K28>=80,2,1))),"—") -> 3
A29: IG-03 | B29: Actividades BTL | C29: 1.3 — Promoción de destinos y productos según estrategia de marca (≥32 activaciones) | D29: % Presup. Ejecutado | E29: 1 | F29: 0.27272727 | G29: Abr-26 | H29: 3 | J29: =IFERROR(LOOKUP(2,1/(I27:I29<>""),I27:I29),"—") -> 0.62 | K29: =IFERROR(IF(OR(J29="—",F29=0),"",J29/F29*100),"—") -> 227.33333 | L29: =IFERROR(IF(K29="","",IF(K29>=95,3,IF(K29>=80,2,1))),"—") -> 3
A30: IG-03 | B30: Actividades BTL | C30: 1.3 — Promoción de destinos y productos según estrategia de marca (≥32 activaciones) | D30: % Presup. Ejecutado | E30: 1 | F30: 0.36363636 | G30: May-26 | H30: 4 | J30: =IFERROR(LOOKUP(2,1/(I27:I30<>""),I27:I30),"—") -> 0.62 | K30: =IFERROR(IF(OR(J30="—",F30=0),"",J30/F30*100),"—") -> 170.5 | L30: =IFERROR(IF(K30="","",IF(K30>=95,3,IF(K30>=80,2,1))),"—") -> 3
A31: IG-03 | B31: Actividades BTL | C31: 1.3 — Promoción de destinos y productos según estrategia de marca (≥32 activaciones) | D31: % Presup. Ejecutado | E31: 1 | F31: 0.45454545 | G31: Jun-26 | H31: 5 | J31: =IFERROR(LOOKUP(2,1/(I27:I31<>""),I27:I31),"—") -> 0.62 | K31: =IFERROR(IF(OR(J31="—",F31=0),"",J31/F31*100),"—") -> 136.4 | L31: =IFERROR(IF(K31="","",IF(K31>=95,3,IF(K31>=80,2,1))),"—") -> 3
A32: IG-03 | B32: Actividades BTL | C32: 1.3 — Promoción de destinos y productos según estrategia de marca (≥32 activaciones) | D32: % Presup. Ejecutado | E32: 1 | F32: 0.54545455 | G32: Jul-26 | H32: 6 | J32: =IFERROR(LOOKUP(2,1/(I27:I32<>""),I27:I32),"—") -> 0.62 | K32: =IFERROR(IF(OR(J32="—",F32=0),"",J32/F32*100),"—") -> 113.66667 | L32: =IFERROR(IF(K32="","",IF(K32>=95,3,IF(K32>=80,2,1))),"—") -> 3
A33: IG-03 | B33: Actividades BTL | C33: 1.3 — Promoción de destinos y productos según estrategia de marca (≥32 activaciones) | D33: % Presup. Ejecutado | E33: 1 | F33: 0.63636364 | G33: Ago-26 | H33: 7 | J33: =IFERROR(LOOKUP(2,1/(I27:I33<>""),I27:I33),"—") -> 0.62 | K33: =IFERROR(IF(OR(J33="—",F33=0),"",J33/F33*100),"—") -> 97.428571 | L33: =IFERROR(IF(K33="","",IF(K33>=95,3,IF(K33>=80,2,1))),"—") -> 3
A34: IG-03 | B34: Actividades BTL | C34: 1.3 — Promoción de destinos y productos según estrategia de marca (≥32 activaciones) | D34: % Presup. Ejecutado | E34: 1 | F34: 0.72727273 | G34: Sep-26 | H34: 8 | J34: =IFERROR(LOOKUP(2,1/(I27:I34<>""),I27:I34),"—") -> 0.62 | K34: =IFERROR(IF(OR(J34="—",F34=0),"",J34/F34*100),"—") -> 85.25 | L34: =IFERROR(IF(K34="","",IF(K34>=95,3,IF(K34>=80,2,1))),"—") -> 2
A35: IG-03 | B35: Actividades BTL | C35: 1.3 — Promoción de destinos y productos según estrategia de marca (≥32 activaciones) | D35: % Presup. Ejecutado | E35: 1 | F35: 0.81818182 | G35: Oct-26 | H35: 9 | J35: =IFERROR(LOOKUP(2,1/(I27:I35<>""),I27:I35),"—") -> 0.62 | K35: =IFERROR(IF(OR(J35="—",F35=0),"",J35/F35*100),"—") -> 75.777778 | L35: =IFERROR(IF(K35="","",IF(K35>=95,3,IF(K35>=80,2,1))),"—") -> 1
A36: IG-03 | B36: Actividades BTL | C36: 1.3 — Promoción de destinos y productos según estrategia de marca (≥32 activaciones) | D36: % Presup. Ejecutado | E36: 1 | F36: 0.90909091 | G36: Nov-26 | H36: 10 | J36: =IFERROR(LOOKUP(2,1/(I27:I36<>""),I27:I36),"—") -> 0.62 | K36: =IFERROR(IF(OR(J36="—",F36=0),"",J36/F36*100),"—") -> 68.2 | L36: =IFERROR(IF(K36="","",IF(K36>=95,3,IF(K36>=80,2,1))),"—") -> 1
A37: IG-03 | B37: Actividades BTL | C37: 1.3 — Promoción de destinos y productos según estrategia de marca (≥32 activaciones) | D37: % Presup. Ejecutado | E37: 1 | F37: 1 | G37: Dic-26 | H37: 11 | J37: =IFERROR(LOOKUP(2,1/(I27:I37<>""),I27:I37),"—") -> 0.62 | K37: =IFERROR(IF(OR(J37="—",F37=0),"",J37/F37*100),"—") -> 62 | L37: =IFERROR(IF(K37="","",IF(K37>=95,3,IF(K37>=80,2,1))),"—") -> 1
A38: IG-04 | B38: Material Promocional POP | C38: 1.4 — Producción y distribución de material POP bajo lineamientos MinCIT | D38: % Presup. Ejecutado | E38: 1 | F38: 0.090909091 | G38: Feb-26 | H38: 1 | I38: 0.31 | J38: =IFERROR(LOOKUP(2,1/(I38:I38<>""),I38:I38),"—") -> 0.31 | K38: =IFERROR(IF(OR(J38="—",F38=0),"",J38/F38*100),"—") -> 341 | L38: =IFERROR(IF(K38="","",IF(K38>=95,3,IF(K38>=80,2,1))),"—") -> 3
A39: IG-04 | B39: Material Promocional POP | C39: 1.4 — Producción y distribución de material POP bajo lineamientos MinCIT | D39: % Presup. Ejecutado | E39: 1 | F39: 0.18181818 | G39: Mar-26 | H39: 2 | J39: =IFERROR(LOOKUP(2,1/(I38:I39<>""),I38:I39),"—") -> 0.31 | K39: =IFERROR(IF(OR(J39="—",F39=0),"",J39/F39*100),"—") -> 170.5 | L39: =IFERROR(IF(K39="","",IF(K39>=95,3,IF(K39>=80,2,1))),"—") -> 3
A40: IG-04 | B40: Material Promocional POP | C40: 1.4 — Producción y distribución de material POP bajo lineamientos MinCIT | D40: % Presup. Ejecutado | E40: 1 | F40: 0.27272727 | G40: Abr-26 | H40: 3 | J40: =IFERROR(LOOKUP(2,1/(I38:I40<>""),I38:I40),"—") -> 0.31 | K40: =IFERROR(IF(OR(J40="—",F40=0),"",J40/F40*100),"—") -> 113.66667 | L40: =IFERROR(IF(K40="","",IF(K40>=95,3,IF(K40>=80,2,1))),"—") -> 3
A41: IG-04 | B41: Material Promocional POP | C41: 1.4 — Producción y distribución de material POP bajo lineamientos MinCIT | D41: % Presup. Ejecutado | E41: 1 | F41: 0.36363636 | G41: May-26 | H41: 4 | J41: =IFERROR(LOOKUP(2,1/(I38:I41<>""),I38:I41),"—") -> 0.31 | K41: =IFERROR(IF(OR(J41="—",F41=0),"",J41/F41*100),"—") -> 85.25 | L41: =IFERROR(IF(K41="","",IF(K41>=95,3,IF(K41>=80,2,1))),"—") -> 2
...

Sheet Curva_S
A1: CURVA-S — AVANCE EJECUCIÓN PRESUPUESTAL | FNTP-2025-264 | Oct-25 – Ago-26 | % Acumulado Programado vs. Ejecutado Real
A2: Feb-26 = Mes 5 del proyecto P264 · 45.1% confirmado · Meses 1-4 (Oct-Ene): anteriores al contrato FNTC-161-2026
A3: Período | B3: Mes P264 | C3: % Programado | D3: % Real Ejecutado | E3: Desviación (pp) | F3: Estado
A4: Oct-25 | B4: Mes 1 | C4: =Datos!C121 -> 0.06 | D4: =IF(Datos!D121="","",Datos!D121) -> 0.0667 | E4: =IFERROR(IF(D4="","",IF(D4="Prev. contrato","",D4-C4)),"") -> 0.0067 | F4: =IFERROR(IF(OR(D4="",D4="Prev. contrato"),"—",IF(E4>=0,"▲ Adelantado",IF(E4>=-0.05,"► En rango","▼ Rezagado"))),"—") -> ▲ Adelantado
A5: Nov-25 | B5: Mes 2 | C5: =Datos!C122 -> 0.14 | D5: =IF(Datos!D122="","",Datos!D122) -> 0.1326 | E5: =IFERROR(IF(D5="","",IF(D5="Prev. contrato","",D5-C5)),"") -> -0.0074 | F5: =IFERROR(IF(OR(D5="",D5="Prev. contrato"),"—",IF(E5>=0,"▲ Adelantado",IF(E5>=-0.05,"► En rango","▼ Rezagado"))),"—") -> ► En rango
A6: Dic-25 | B6: Mes 3 | C6: =Datos!C123 -> 0.24 | D6: =IF(Datos!D123="","",Datos!D123) -> 0.3307 | E6: =IFERROR(IF(D6="","",IF(D6="Prev. contrato","",D6-C6)),"") -> 0.0907 | F6: =IFERROR(IF(OR(D6="",D6="Prev. contrato"),"—",IF(E6>=0,"▲ Adelantado",IF(E6>=-0.05,"► En rango","▼ Rezagado"))),"—") -> ▲ Adelantado
A7: Ene-26 | B7: Mes 4 | C7: =Datos!C124 -> 0.36 | D7: =IF(Datos!D124="","",Datos!D124) -> 0.354 | E7: =IFERROR(IF(D7="","",IF(D7="Prev. contrato","",D7-C7)),"") -> -0.006 | F7: =IFERROR(IF(OR(D7="",D7="Prev. contrato"),"—",IF(E7>=0,"▲ Adelantado",IF(E7>=-0.05,"► En rango","▼ Rezagado"))),"—") -> ► En rango
A8: Feb-26 | B8: Mes 5 | C8: =Datos!C125 -> 0.48 | D8: =IF(Datos!D125="","",Datos!D125) -> 0.398 | E8: =IFERROR(IF(D8="","",IF(D8="Prev. contrato","",D8-C8)),"") -> -0.082 | F8: =IFERROR(IF(OR(D8="",D8="Prev. contrato"),"—",IF(E8>=0,"▲ Adelantado",IF(E8>=-0.05,"► En rango","▼ Rezagado"))),"—") -> ▼ Rezagado
A9: Mar-26 | B9: Mes 6 | C9: =Datos!C126 -> 0.59 | D9: =IF(Datos!D126="","",Datos!D126) | E9: =IFERROR(IF(D9="","",IF(D9="Prev. contrato","",D9-C9)),"") | F9: =IFERROR(IF(OR(D9="",D9="Prev. contrato"),"—",IF(E9>=0,"▲ Adelantado",IF(E9>=-0.05,"► En rango","▼ Rezagado"))),"—") -> —
A10: Abr-26 | B10: Mes 7 | C10: =Datos!C127 -> 0.7 | D10: =IF(Datos!D127="","",Datos!D127) | E10: =IFERROR(IF(D10="","",IF(D10="Prev. contrato","",D10-C10)),"") | F10: =IFERROR(IF(OR(D10="",D10="Prev. contrato"),"—",IF(E10>=0,"▲ Adelantado",IF(E10>=-0.05,"► En rango","▼ Rezagado"))),"—") -> —
A11: May-26 | B11: Mes 8 | C11: =Datos!C128 -> 0.8 | D11: =IF(Datos!D128="","",Datos!D128) | E11: =IFERROR(IF(D11="","",IF(D11="Prev. contrato","",D11-C11)),"") | F11: =IFERROR(IF(OR(D11="",D11="Prev. contrato"),"—",IF(E11>=0,"▲ Adelantado",IF(E11>=-0.05,"► En rango","▼ Rezagado"))),"—") -> —
A12: Jun-26 | B12: Mes 9 | C12: =Datos!C129 -> 0.88 | D12: =IF(Datos!D129="","",Datos!D129) | E12: =IFERROR(IF(D12="","",IF(D12="Prev. contrato","",D12-C12)),"") | F12: =IFERROR(IF(OR(D12="",D12="Prev. contrato"),"—",IF(E12>=0,"▲ Adelantado",IF(E12>=-0.05,"► En rango","▼ Rezagado"))),"—") -> —
A13: Jul-26 | B13: Mes 10 | C13: =Datos!C130 -> 0.95 | D13: =IF(Datos!D130="","",Datos!D130) | E13: =IFERROR(IF(D13="","",IF(D13="Prev. contrato","",D13-C13)),"") | F13: =IFERROR(IF(OR(D13="",D13="Prev. contrato"),"—",IF(E13>=0,"▲ Adelantado",IF(E13>=-0.05,"► En rango","▼ Rezagado"))),"—") -> —
A14: Ago-26 | B14: Mes 11 | C14: =Datos!C131 -> 1 | D14: =IF(Datos!D131="","",Datos!D131) | E14: =IFERROR(IF(D14="","",IF(D14="Prev. contrato","",D14-C14)),"") | F14: =IFERROR(IF(OR(D14="",D14="Prev. contrato"),"—",IF(E14>=0,"▲ Adelantado",IF(E14>=-0.05,"► En rango","▼ Rezagado"))),"—") -> —
A16: FUENTE: % Real = dato ingresado en Datos Sección B. Meses 1-4 son previos al contrato FNTC-161-2026.

Sheet Dashboard
B2: TABLERO DE CONTROL EJECUTIVO — FNTC-161-2026 | Patrimonio Autónomo FONTUR
B3: Proyecto FNTP-2025-264 · Oct-25 – Ago-26 · Contrato: Feb–Dic 2026
B5: GESTIÓN POR ACTIVIDAD — % Desempeño vs. Meta Proporcional al Mes
B6: Cód. | C6: Indicador / Actividad | D6: Unidad | E6: Meta Total | F6: Meta Acum. | G6: Último Acum. | H6: % Desempeño | I6: Estado | J6: Semáforo
B7: =Datos!A5 -> IG-01 | C7: =Datos!B5 -> Diseño Material Gráfico | D7: =Datos!D5 -> % Presup. Ejecutado | E7: =Datos!E5 -> 1 | F7: =IFERROR(LOOKUP(2,1/(Datos!I5:I15<>""),Datos!F5:F15),"—") -> 0.090909091 | G7: =IFERROR(LOOKUP(2,1/(Datos!I5:I15<>""),Datos!J5:J15),"—") -> 0.45 | H7: {=IFERROR(IF(LOOKUP(2,1/(Datos!I5:I15<>""),Datos!K5:K15)="","S/D",LOOKUP(2,1/(Datos!I5:I15<>""),Datos!K5:K15)),"S/D")} -> 495 | I7: =IFERROR(_xlfn.LET(_xlpm.s,LOOKUP(2,1/(Datos!I5:I15<>""),Datos!L5:L15),IF(_xlpm.s=3,"CUMPLE",IF(_xlpm.s=2,"Observación","Crítico"))),"S/D") -> CUMPLE | J7: =IFERROR(IF(H7="","",IF(H7>=95,3,IF(H7>=80,2,1))),"—") -> 3
B8: =Datos!A16 -> IG-02 | C8: =Datos!B16 -> Ejecución Pauta | D8: =Datos!D16 -> % Presup. Ejecutado | E8: =Datos!E16 -> 1 | F8: =IFERROR(LOOKUP(2,1/(Datos!I16:I26<>""),Datos!F16:F26),"—") -> 0.090909091 | G8: =IFERROR(LOOKUP(2,1/(Datos!I16:I26<>""),Datos!J16:J26),"—") -> 0.58 | H8: {=IFERROR(IF(LOOKUP(2,1/(Datos!I16:I26<>""),Datos!K16:K26)="","S/D",LOOKUP(2,1/(Datos!I16:I26<>""),Datos!K16:K26)),"S/D")} -> 638 | I8: =IFERROR(_xlfn.LET(_xlpm.s,LOOKUP(2,1/(Datos!I16:I26<>""),Datos!L16:L26),IF(_xlpm.s=3,"CUMPLE",IF(_xlpm.s=2,"Observación","Crítico"))),"S/D") -> CUMPLE | J8: =IFERROR(IF(H8="","",IF(H8>=95,3,IF(H8>=80,2,1))),"—") -> 3
B9: =Datos!A27 -> IG-03 | C9: =Datos!B27 -> Actividades BTL | D9: =Datos!D27 -> % Presup. Ejecutado | E9: =Datos!E27 -> 1 | F9: =IFERROR(LOOKUP(2,1/(Datos!I27:I37<>""),Datos!F27:F37),"—") -> 0.090909091 | G9: =IFERROR(LOOKUP(2,1/(Datos!I27:I37<>""),Datos!J27:J37),"—") -> 0.62 | H9: {=IFERROR(IF(LOOKUP(2,1/(Datos!I27:I37<>""),Datos!K27:K37)="","S/D",LOOKUP(2,1/(Datos!I27:I37<>""),Datos!K27:K37)),"S/D")} -> 682 | I9: =IFERROR(_xlfn.LET(_xlpm.s,LOOKUP(2,1/(Datos!I27:I37<>""),Datos!L27:L37),IF(_xlpm.s=3,"CUMPLE",IF(_xlpm.s=2,"Observación","Crítico"))),"S/D") -> CUMPLE | J9: =IFERROR(IF(H9="","",IF(H9>=95,3,IF(H9>=80,2,1))),"—") -> 3
B10: =Datos!A38 -> IG-04 | C10: =Datos!B38 -> Material Promocional POP | D10: =Datos!D38 -> % Presup. Ejecutado | E10: =Datos!E38 -> 1 | F10: =IFERROR(LOOKUP(2,1/(Datos!I38:I48<>""),Datos!F38:F48),"—") -> 0.090909091 | G10: =IFERROR(LOOKUP(2,1/(Datos!I38:I48<>""),Datos!J38:J48),"—") -> 0.31 | H10: {=IFERROR(IF(LOOKUP(2,1/(Datos!I38:I48<>""),Datos!K38:K48)="","S/D",LOOKUP(2,1/(Datos!I38:I48<>""),Datos!K38:K48)),"S/D")} -> 341 | I10: =IFERROR(_xlfn.LET(_xlpm.s,LOOKUP(2,1/(Datos!I38:I48<>""),Datos!L38:L48),IF(_xlpm.s=3,"CUMPLE",IF(_xlpm.s=2,"Observación","Crítico"))),"S/D") -> CUMPLE | J10: =IFERROR(IF(H10="","",IF(H10>=95,3,IF(H10>=80,2,1))),"—") -> 3
B11: =Datos!A49 -> IG-05 | C11: =Datos!B49 -> Viajes de Familiarización | D11: =Datos!D49 -> % Presup. Ejecutado | E11: =Datos!E49 -> 1 | F11: =IFERROR(LOOKUP(2,1/(Datos!I49:I59<>""),Datos!F49:F59),"—") -> 0.090909091 | G11: =IFERROR(LOOKUP(2,1/(Datos!I49:I59<>""),Datos!J49:J59),"—") -> 0.14 | H11: {=IFERROR(IF(LOOKUP(2,1/(Datos!I49:I59<>""),Datos!K49:K59)="","S/D",LOOKUP(2,1/(Datos!I49:I59<>""),Datos!K49:K59)),"S/D")} -> 154 | I11: =IFERROR(_xlfn.LET(_xlpm.s,LOOKUP(2,1/(Datos!I49:I59<>""),Datos!L49:L59),IF(_xlpm.s=3,"CUMPLE",IF(_xlpm.s=2,"Observación","Crítico"))),"S/D") -> CUMPLE | J11: =IFERROR(IF(H11="","",IF(H11>=95,3,IF(H11>=80,2,1))),"—") -> 3
B12: =Datos!A60 -> IG-06 | C12: =Datos!B60 -> Embajadores de Marca | D12: =Datos!D60 -> Emb. Vinculados / 6 | E12: =Datos!E60 -> 1 | F12: =IFERROR(LOOKUP(2,1/(Datos!I60:I70<>""),Datos!F60:F70),"—") -> 0.090909091 | G12: =IFERROR(LOOKUP(2,1/(Datos!I60:I70<>""),Datos!J60:J70),"—") -> 0 | H12: {=IFERROR(IF(LOOKUP(2,1/(Datos!I60:I70<>""),Datos!K60:K70)="","S/D",LOOKUP(2,1/(Datos!I60:I70<>""),Datos!K60:K70)),"S/D")} -> 0 | I12: =IFERROR(_xlfn.LET(_xlpm.s,LOOKUP(2,1/(Datos!I60:I70<>""),Datos!L60:L70),IF(_xlpm.s=3,"CUMPLE",IF(_xlpm.s=2,"Observación","Crítico"))),"S/D") -> Crítico | J12: =IFERROR(IF(H12="","",IF(H12>=95,3,IF(H12>=80,2,1))),"—") -> 1
B13: =Datos!A71 -> IG-07 | C13: =Datos!B71 -> Plataforma IA | D13: =Datos!D71 -> % Avance desarrollo | E13: =Datos!E71 -> 1 | F13: =IFERROR(LOOKUP(2,1/(Datos!I71:I81<>""),Datos!F71:F81),"—") -> 0.090909091 | G13: =IFERROR(LOOKUP(2,1/(Datos!I71:I81<>""),Datos!J71:J81),"—") -> 0 | H13: {=IFERROR(IF(LOOKUP(2,1/(Datos!I71:I81<>""),Datos!K71:K81)="","S/D",LOOKUP(2,1/(Datos!I71:I81<>""),Datos!K71:K81)),"S/D")} -> 0 | I13: =IFERROR(_xlfn.LET(_xlpm.s,LOOKUP(2,1/(Datos!I71:I81<>""),Datos!L71:L81),IF(_xlpm.s=3,"CUMPLE",IF(_xlpm.s=2,"Observación","Crítico"))),"S/D") -> Crítico | J13: =IFERROR(IF(H13="","",IF(H13>=95,3,IF(H13>=80,2,1))),"—") -> 1
B14: =Datos!A82 -> IG-08 | C14: =Datos!B82 -> Macro Ruedas de Negocio | D14: =Datos!D82 -> Eventos Realizados / 6 | E14: =Datos!E82 -> 1 | F14: =IFERROR(LOOKUP(2,1/(Datos!I82:I92<>""),Datos!F82:F92),"—") -> 0.090909091 | G14: =IFERROR(LOOKUP(2,1/(Datos!I82:I92<>""),Datos!J82:J92),"—") -> 0 | H14: {=IFERROR(IF(LOOKUP(2,1/(Datos!I82:I92<>""),Datos!K82:K92)="","S/D",LOOKUP(2,1/(Datos!I82:I92<>""),Datos!K82:K92)),"S/D")} -> 0 | I14: =IFERROR(_xlfn.LET(_xlpm.s,LOOKUP(2,1/(Datos!I82:I92<>""),Datos!L82:L92),IF(_xlpm.s=3,"CUMPLE",IF(_xlpm.s=2,"Observación","Crítico"))),"S/D") -> Crítico | J14: =IFERROR(IF(H14="","",IF(H14>=95,3,IF(H14>=80,2,1))),"—") -> 1
B15: =Datos!A93 -> IG-09 | C15: =Datos!B93 -> Estudio de Impacto | D15: =Datos!D93 -> % Etapas completadas | E15: =Datos!E93 -> 1 | F15: =IFERROR(LOOKUP(2,1/(Datos!I93:I103<>""),Datos!F93:F103),"—") -> 0.090909091 | G15: =IFERROR(LOOKUP(2,1/(Datos!I93:I103<>""),Datos!J93:J103),"—") -> 0 | H15: {=IFERROR(IF(LOOKUP(2,1/(Datos!I93:I103<>""),Datos!K93:K103)="","S/D",LOOKUP(2,1/(Datos!I93:I103<>""),Datos!K93:K103)),"S/D")} -> 0 | I15: =IFERROR(_xlfn.LET(_xlpm.s,LOOKUP(2,1/(Datos!I93:I103<>""),Datos!L93:L103),IF(_xlpm.s=3,"CUMPLE",IF(_xlpm.s=2,"Observación","Crítico"))),"S/D") -> Crítico | J15: =IFERROR(IF(H15="","",IF(H15>=95,3,IF(H15>=80,2,1))),"—") -> 1
B16: =Datos!A104 -> IG-10 | C16: =Datos!B104 -> Personal de Seguimiento | D16: =Datos!D104 -> Informes Aprobados / 11 | E16: =Datos!E104 -> 1 | F16: =IFERROR(LOOKUP(2,1/(Datos!I104:I114<>""),Datos!F104:F114),"—") -> 0.090909091 | G16: =IFERROR(LOOKUP(2,1/(Datos!I104:I114<>""),Datos!J104:J114),"—") -> 0.090909091 | H16: {=IFERROR(IF(LOOKUP(2,1/(Datos!I104:I114<>""),Datos!K104:K114)="","S/D",LOOKUP(2,1/(Datos!I104:I114<>""),Datos!K104:K114)),"S/D")} -> 100 | I16: =IFERROR(_xlfn.LET(_xlpm.s,LOOKUP(2,1/(Datos!I104:I114<>""),Datos!L104:L114),IF(_xlpm.s=3,"CUMPLE",IF(_xlpm.s=2,"Observación","Crítico"))),"S/D") -> CUMPLE | J16: =IFERROR(IF(H16="","",IF(H16>=95,3,IF(H16>=80,2,1))),"—") -> 3
B19: CURVA-S — EJECUCIÓN PRESUPUESTAL P264 | Oct-25–Ago-26 | Feb-26=Mes5 (45.1%)
B20: Concepto | C20: Oct-25 | D20: Nov-25 | E20: Dic-25 | F20: Ene-26 | G20: Feb-26 | H20: Mar-26 | I20: Abr-26 | J20: May-26 | K20: Jun-26 | L20: Jul-26 | M20: Ago-26 | N20: Ref.
B21: Programado | C21: =IF(Datos!C121="","",Datos!C121) -> 0.06 | D21: =IF(Datos!C122="","",Datos!C122) -> 0.14 | E21: =IF(Datos!C123="","",Datos!C123) -> 0.24 | F21: =IF(Datos!C124="","",Datos!C124) -> 0.36 | G21: =IF(Datos!C125="","",Datos!C125) -> 0.48 | H21: =IF(Datos!C126="","",Datos!C126) -> 0.59 | I21: =IF(Datos!C127="","",Datos!C127) -> 0.7 | J21: =IF(Datos!C128="","",Datos!C128) -> 0.8 | K21: =IF(Datos!C129="","",Datos!C129) -> 0.88 | L21: =IF(Datos!C130="","",Datos!C130) -> 0.95 | M21: =IF(Datos!C131="","",Datos!C131) -> 1 | N21: → Datos §B
B22: Real P264 | C22: =IF(Datos!D121="","",Datos!D121) -> 0.0667 | D22: =IF(Datos!D122="","",Datos!D122) -> 0.1326 | E22: =IF(Datos!D123="","",Datos!D123) -> 0.3307 | F22: =IF(Datos!D124="","",Datos!D124) -> 0.354 | G22: =IF(Datos!D125="","",Datos!D125) -> 0.398 | H22: =IF(Datos!D126="","",Datos!D126) | I22: =IF(Datos!D127="","",Datos!D127) | J22: =IF(Datos!D128="","",Datos!D128) | K22: =IF(Datos!D129="","",Datos!D129) | L22: =IF(Datos!D130="","",Datos!D130) | M22: =IF(Datos!D131="","",Datos!D131) | N22: → Datos §B
B23: Desviación | C23: =IF(Datos!E121="","",Datos!E121) -> 0.0067 | D23: =IF(Datos!E122="","",Datos!E122) -> -0.0074 | E23: =IF(Datos!E123="","",Datos!E123) -> 0.0907 | F23: =IF(Datos!E124="","",Datos!E124) -> -0.006 | G23: =IF(Datos!E125="","",Datos!E125) -> -0.082 | H23: =IF(Datos!E126="","",Datos!E126) | I23: =IF(Datos!E127="","",Datos!E127) | J23: =IF(Datos!E128="","",Datos!E128) | K23: =IF(Datos!E129="","",Datos!E129) | L23: =IF(Datos!E130="","",Datos!E130) | M23: =IF(Datos!E131="","",Datos!E131) | N23: → Datos §B
B25: INDICADORES DE RESULTADO — Impacto Estratégico Campaña Colombia El País De La Belleza
B26: Cód. | C26: Indicador de Resultado | D26: Unidad | E26: Meta | F26: Último Acum. | G26: % Avance
B27: =Datos!A136 -> IR-01 | C27: =Datos!B136 -> Alcance e Impacto en Medios | D27: =Datos!D136 -> N° impactos digitales y ATL | E27: =Datos!E136 -> 135000000 | F27: =Datos!I146 -> 0 | G27: =Datos!J146
B28: =Datos!A147 -> IR-02 | C28: =Datos!B147 -> Generación de Oportunidades Comerciales | D28: =Datos!D147 -> N° expectativas de negocio | E28: =Datos!E147 -> 1200 | F28: =Datos!I157 -> 0 | G28: =Datos!J157
B29: =Datos!A158 -> IR-03 | C29: =Datos!B158 -> Medición de Impacto de Campaña | D29: =Datos!D158 -> N° estudios realizados | E29: =Datos!E158 -> 1 | F29: =Datos!I168 -> 0 | G29: =Datos!J168
B30: =Datos!A169 -> IR-04 | C30: =Datos!B169 -> Implementación Tecnológica (IA) | D30: =Datos!D169 -> N° plataformas operativas | E30: =Datos!E169 -> 1 | F30: =Datos!I179 -> 0 | G30: =Datos!J179
B33: LEYENDA SEMÁFORO
B34: 🟢 CUMPLE ≥ 95% | G34: 🟡 Observación 80–94% | L34: 🔴 Crítico < 80%
B35: ⚠ Datos en hoja 'Datos': Sec.A col I (valor real por IG×mes) | Sec.B fila Real P264 | Sec.C col H (valor IR×mes). % Desempeño = Real / Meta Acum. Mes × 100 (meta proporcional al mes, no la meta total).

Sheet Hallazgos
A1: REGISTRO DE HALLAZGOS Y ACCIONES DE MITIGACIÓN | FNTC-161-2026
A2: # | B2: Período | C2: Hallazgo / Riesgo | D2: Estado | E2: Acción Mitigante | F2: Responsable | G2: Fecha Cierre
A3: 1 | B3: Feb-26 | C3: Retraso entrega material por agencia externa | D3: Crítico | E3: Escalar a comité de mercadeo; ajuste de cronograma. | F3: Gerente de Proyecto
A4: 2 | B4: Feb-26 | C4: Baja interacción digital Amazonía y Macizo | D4: Observación | E4: Reforzar pauta digital focalizada con segmentación regional. | F4: Líder Digital
A5: 3 | B5: Feb-26 | C5: Riesgo subejecución Amazonía y Macizo al cierre Q1 | D5: Observación | E5: Alinear cronograma táctico con agencia antes del cierre de trimestre. | F5: Coordinador Financiero
A6: 4 | B6: Feb-26 | C6: Flujos Pauta/BTL pendientes calibración MinCIT/FONTUR | D6: Observación | E6: Calibración y retroalimentación para normalizar umbrales Curva-S. | F6: Contratista | G6: Mar-26
A17: Agregar filas según se detecten hallazgos. Estado: Crítico / Observación / Resuelto.
